<html>
<head>
	<meta charset="utf-8">
	<meta name="viewport" content="width=device-width, initial-scale=1">
	<link rel="stylesheet" id="themeJQ" href="../../css/themes/default/theme-default.min.css"/>
	<link rel="stylesheet" href="../../css/themes/default/jquery.mobile.structure-1.2.0.min.css"/>
	<link rel="stylesheet" id="themeDocs" href="../../css/docs-default.css"/>
	<script src="../../js/energize-min.js"></script>
	<script src="../../js/jquery-1.8.1.min.js"></script>
	<script src="../../../app.js"></script>
	<script src="../../js/common.js"></script>
	<script src="../../js/example.js"></script>
	<script src="../../js/jquery.mobile-1.2.0.min.js"></script>
	
	<link href="../css/docs.css" rel="stylesheet" type="text/css"/>
	<link href="../css/mathml.css" rel="stylesheet" type="text/css"/>

	<script> function jsxref(a,b,c,d,e) { document.write("<b>"+b+"</b>"); }</script>
	<script> function Note(s) { document.write("Note: "+s); }</script>
	<script> function anch(s) { document.write(s); }</script>
</head>
 
<body>

<div data-role="page" data-theme="a" data-ajax="false">

	<div data-role="header" data-position="fixed">
		<a href='#' class='ui-btn-left' data-icon='arrow-l' data-theme="c" onclick="history.back(); return false">Back</a> <h1>try...catch</h1>
	</div><!-- /header -->

	<div data-role="content">
		<div><h2>try...catch</h2></div>

<p>The <strong><code>try...catch</code> statement</strong> marks a block of statements to try, and specifies a response, should an exception be thrown.</p>

<h2 id="Syntax">Syntax</h2>

<pre class="syntaxbox">try {
   <em>try_statements</em>
}
[catch (<em>exception_var_1</em> if <em>condition_1</em>) { // non-standard
   <em>catch_statements_1</em>
}]
...
[catch (<em>exception_var_2</em>) {
   <em>catch_statements_2</em>
}]
[finally {
   <em>finally_statements</em>
}]
</pre>

<dl>
 <dt><code>try_statements</code></dt>
 <dd>The statements to be executed.</dd>
</dl>

<dl>
 <dt><code>catch_statements_1</code>, <code>catch_statements_2</code></dt>
 <dd>Statements that are executed if an exception is thrown in the <code>try</code> block.</dd>
</dl>

<dl>
 <dt><code>exception_var_1</code>, <code>exception_var_2</code></dt>
 <dd>An identifier to hold an exception object for the associated <code>catch</code> clause.</dd>
</dl>

<dl>
 <dt><code>condition_1</code></dt>
 <dd>A conditional expression.</dd>
</dl>

<dl>
 <dt><code>finally_statements</code></dt>
 <dd>Statements that are executed after the <code>try</code> statement completes. These statements execute regardless of whether or not an exception was thrown or caught.</dd>
</dl>

<h2 id="Description">Description</h2>

<p>The <code>try</code> statement consists of a <code>try</code> block, which contains one or more statements, and at least one <code>catch</code> clause or a <code>finally</code> clause, or both. That is, there are three forms of the <code>try</code> statement:</p>

<ol>
 <li><code>try...catch</code></li>
 <li><code>try...finally</code></li>
 <li><code>try...catch...finally</code></li>
</ol>

<p>A <code>catch</code> clause contain statements that specify what to do if an exception is thrown in the <code>try</code> block. That is, you want the <code>try</code> block to succeed, and if it does not succeed, you want control to pass to the <code>catch</code> block. If any statement within the <code>try</code> block (or in a function called from within the <code>try</code> block) throws an exception, control immediately shifts to the <code>catch</code> clause. If no exception is thrown in the <code>try</code> block, the <code>catch</code> clause is skipped.</p>

<p>The <code>finally</code> clause executes after the <code>try</code> block and <code>catch</code> clause(s) execute but before the statements following the <code>try</code> statement. It always executes, regardless of whether or not an exception was thrown or caught.</p>

<p>You can nest one or more <code>try</code> statements. If an inner <code>try</code> statement does not have a <code>catch</code> clause, the enclosing <code>try</code> statement's <code>catch</code> clause is entered.</p>

<p>You also use the <code>try</code> statement to handle JavaScript exceptions. See the JavaScript Guide for more information on JavaScript exceptions.</p>

<h3 id="Unconditional_catch_clause">Unconditional <code>catch</code> clause</h3>

<p>When a single, unconditional <code>catch</code> clause is used, the <code>catch</code> block is entered when any exception is thrown. For example, when the exception occurs in the following code, control transfers to the <code>catch</code> clause.</p>

<pre class="brush: js">try {
   throw "myException"; // generates an exception
}
catch (e) {
   // statements to handle any exceptions
   logMyErrors(e); // pass exception object to error handler
}
</pre>

<h3 id="Conditional_catch_clauses">Conditional <code>catch</code> clauses</h3>

<p></p>

<p>You can also use one or more conditional <code>catch</code> clauses to handle specific exceptions. In this case, the appropriate <code>catch</code> clause is entered when the specified exception is thrown. In the following example, code in the <code>try</code> block can potentially throw three exceptions: <b>TypeError</b>, <b>RangeError</b>, and <b>EvalError</b>. When an exception occurs, control transfers to the appropriate <code>catch</code> clause. If the exception is not one of the specified exceptions and an unconditional <code>catch</code> clause is found, control transfers to that <code>catch</code> clause.</p>

<p>If you use an unconditional <code>catch</code> clause with one or more conditional <code>catch</code> clauses, the unconditional <code>catch</code> clause must be specified last. Otherwise, the unconditional <code>catch</code> clause will intercept all types of exception before they can reach the conditional ones.</p>

<p>Reminder: this functionality is not part of the ECMAScript specification.</p>

<pre class="brush: js">try {
    myroutine(); // may throw three types of exceptions
} catch (e if e instanceof TypeError) {
    // statements to handle TypeError exceptions
} catch (e if e instanceof RangeError) {
    // statements to handle RangeError exceptions
} catch (e if e instanceof EvalError) {
    // statements to handle EvalError exceptions
} catch (e) {
    // statements to handle any unspecified exceptions
    logMyErrors(e); // pass exception object to error handler
}
</pre>

<p>And here is how to do implement the same "Conditional catch clauses" using only simple JavaScript conforming to the ECMAScript specification (obviously it's more verbose, but works everywhere):</p>

<pre class="brush: js">try {
    myroutine(); // may throw three types of exceptions
} catch (e) {
    if (e instanceof TypeError) {
        // statements to handle TypeError exceptions
    } else if (e instanceof RangeError) {
        // statements to handle RangeError exceptions
    } else if (e instanceof EvalError) {
        // statements to handle EvalError exceptions
    } else {
       // statements to handle any unspecified exceptions
       logMyErrors(e); // pass exception object to error handler
    }
}
</pre>

<h3 id="The_exception_identifier">The exception identifier</h3>

<p>When an exception is thrown in the <code>try</code> block, <em><code>exception_var</code></em> (e.g. the <code>e</code> in <code>catch (e)</code>) holds the value specified by the <code>throw</code> statement. You can use this identifier to get information about the exception that was thrown.</p>

<p>This identifier is local to the <code>catch</code> clause. That is, it is created when the <code>catch</code> clause is entered, and after the <code>catch</code> clause finishes executing, the identifier is no longer available.</p>

<h3 id="The_finally_clause">The <code>finally</code> clause</h3>

<p>The <code>finally</code> clause contains statements to execute after the <code>try</code> block and <code>catch</code> clause(s) execute, but before the statements following the <code>try</code> statement. The <code>finally</code> clause executes regardless of whether or not an exception is thrown. If an exception is thrown, the statements in the <code>finally</code> clause execute even if no <code>catch</code> clause handles the exception.</p>

<p>You can use the <code>finally</code> clause to make your script fail gracefully when an exception occurs; for example, you may need to release a resource that your script has tied up. The following example opens a file and then executes statements that use the file (server-side JavaScript allows you to access files). If an exception is thrown while the file is open, the <code>finally</code> clause closes the file before the script fails.</p>

<pre class="brush: js">openMyFile()
try {
   // tie up a resource
   writeMyFile(theData);
}
finally {
   closeMyFile(); // always close the resource
}
</pre>

<h2 id="Examples">Examples</h2>

<h3 id="Nested_try-blocks">Nested try-blocks</h3>

<p>First let's see what happens with this:</p>

<pre class="brush: js">try {
  try {
    throw new Error("oops");
  }
  finally {
    console.log("finally");
  }
}
catch (ex) {
  console.error("outer", ex.message);
}

// Output:
// "finally"
// "outer" "oops"
</pre>

<p>Now, if we already caught the exception in the inner try-block by adding a catch block</p>

<pre class="brush: js">try {
  try {
    throw new Error("oops");
  }
  catch (ex) {
    console.error("inner", ex.message);
  }
  finally {
    console.log("finally");
  }
}
catch (ex) {
  console.error("outer", ex.message);
}

// Output:
// "inner" "oops"
// "finally"
</pre>

<p>And now, lets re-throw the error.</p>

<pre class="brush: js">try {
  try {
    throw new Error("oops");
  }
  catch (ex) {
    console.error("inner", ex.message);
    throw ex;
  }
  finally {
    console.log("finally");
  }
}
catch (ex) {
  console.error("outer", ex.message);
}

// Output:
// "inner" "oops"
// "finally"
// "outer" "oops"
</pre>

<p>Any given exception will be caught only once by the nearest enclosing catch-block, unless it is re-thrown. Of course, any new exceptions raised in the "inner" block (because code in catch-block may do something that throws), will be caught by the "outer" block.</p>

<h3 id="Returning_from_a_finally_block">Returning from a finally block</h3>

<p>If the <code>finally</code> block returns a value, this value becomes the return value of the entire <code>try-catch-finally</code> production, regardless of any <code>return</code> statements in the <code>try</code> and <code>catch</code> blocks. This includes exceptions thrown inside of the catch block:</p>

<pre class="brush: js">try {
  try {
    throw new Error("oops");
  }
  catch (ex) {
    console.error("inner", ex.message);
    throw ex;
  }
  finally {
    console.log("finally");
    return;
  }
}
catch (ex) {
  console.error("outer", ex.message);
}

// Output:
// "inner" "oops"
// "finally"
</pre>

<p>The outer "oops" is not thrown because of the return in the finally block. The same would apply to any value returned from the catch block.</p>







<p></p>







 
		<br>
		<p class="lic">&nbsp;<a class="lic" id="extLink" href="http://developer.mozilla.org/en-US/docs/Web/JavaScript/Reference" target="_blank" data-role="none">
		Created by Mozilla Contributors</a>, license: <a class="lic" id="extLink" href="http://creativecommons.org/licenses/by-sa/2.5" target="_blank" data-role="none">CC-BY-SA 2.5</a>
		</p>
	</div>
</div>

</body>
</html>
 